import { NextFunction, Request, Response } from 'express';
import { Error as MongooseError } from 'mongoose';
import Product from '../models/product';
import BadRequestError from '../errors/bad-request-error';
import ConflictError from '../errors/conflict-error';

export const getProducts = async (_req: Request, res: Response, next: NextFunction) => {
  try {
    const products = await Product.find();

    const response = {
      items: products,
      total: products.length,
    };

    res.status(200).json(response);

    return null;
  } catch (error) {
    return next(error);
  }
};

export const createProduct = async (req: Request, res: Response, next: NextFunction) => {
  try {
    const {
      title, image, category, description, price,
    } = req.body;

    const newProduct = new Product({
      title,
      image,
      category,
      description,
      price,
    });

    const savedProduct = await newProduct.save();
    res.status(201).json(savedProduct);

    return null;
  } catch (error) {
    if (error instanceof MongooseError.ValidationError) {
      return next(new BadRequestError(error.message));
    }
    if (error instanceof Error && error.message.includes('E11000')) {
      return next(new ConflictError('Продукт с таким именем уже существует.'));
    }
    return next(error);
  }
};
